<?xml version="1.0"?>
<robot name="simple_arm">

  <!-- ======================================= -->
  <!-- MATERIALS (Colors for Visualization)    -->
  <!-- ======================================= -->
  <material name="black">
    <color rgba="0.0 0.0 0.0 1.0"/>
  </material>
  
  <material name="blue">
    <color rgba="0.0 0.0 0.8 1.0"/>
  </material>

  <material name="orange">
    <color rgba="1.0 0.5 0.0 1.0"/>
  </material>

  <!-- ======================================= -->
  <!-- LINKS (The rigid parts of the arm)      -->
  <!-- ======================================= -->
  
  <!-- 1. World/Base Link -->
  <link name="base_link">
    <visual>
      <origin xyz="0 0 0" rpy="0 0 0"/>
      <geometry>
        <cylinder radius="0.2" length="0.1"/>
      </geometry>
      <material name="black"/>
    </visual>
  </link>

  <!-- 2. Upper Arm Link -->
  <link name="upper_arm">
    <visual>
      <origin xyz="0 0 0.5" rpy="0 0 0"/>
      <geometry>
        <cylinder radius="0.05" length="1.0"/>
      </geometry>
      <material name="orange"/>
    </visual>
  </link>

  <!-- 3. Forearm Link -->
  <link name="forearm">
    <visual>
      <origin xyz="0 0 0.4" rpy="0 0 0"/>
      <geometry>
        <cylinder radius="0.04" length="0.8"/>
      </geometry>
      <material name="blue"/>
    </visual>
  </link>

  <!-- ======================================= -->
  <!-- JOINTS (How the links are connected)    -->
  <!-- ======================================= -->

  <!-- 1. Shoulder Joint (Revolute: Rotates on Z axis) -->
  <joint name="shoulder_joint" type="revolute">
    <parent link="base_link"/>
    <child link="upper_arm"/>
    <origin xyz="0 0 0.1" rpy="0 0 0"/>
    <axis xyz="0 0 1"/>
    <limit lower="-1.57" upper="1.57" effort="100.0" velocity="1.0"/>
  </joint>

  <!-- 2. Elbow Joint (Revolute: Rotates on Y axis) -->
  <joint name="elbow_joint" type="revolute">
    <parent link="upper_arm"/>
    <child link="forearm"/>
    <origin xyz="0 0 0.9" rpy="0 0 0"/>
    <axis xyz="0 1 0"/>
    <limit lower="-1.57" upper="1.57" effort="100.0" velocity="1.0"/>
  </joint>

</robot>
