<?xml version="1.0"?>
<!--
  Same robot as simple_robot.urdf (base_link -> upper_arm -> forearm,
  via shoulder_joint and elbow_joint), but with links and joints
  declared in reverse order. Used to test that load_urdf's parent/child
  index resolution is independent of file order, not just lucky.
-->
<robot name="simple_arm">

  <material name="black">
    <color rgba="0.0 0.0 0.0 1.0"/>
  </material>

  <material name="blue">
    <color rgba="0.0 0.0 0.8 1.0"/>
  </material>

  <material name="orange">
    <color rgba="1.0 0.5 0.0 1.0"/>
  </material>

  <!-- Links, reversed: forearm, upper_arm, base_link -->
  <link name="forearm">
    <visual>
      <origin xyz="0 0 0.4" rpy="0 0 0"/>
      <geometry>
        <cylinder radius="0.04" length="0.8"/>
      </geometry>
      <material name="blue"/>
    </visual>
  </link>

  <link name="upper_arm">
    <visual>
      <origin xyz="0 0 0.5" rpy="0 0 0"/>
      <geometry>
        <cylinder radius="0.05" length="1.0"/>
      </geometry>
      <material name="orange"/>
    </visual>
  </link>

  <link name="base_link">
    <visual>
      <origin xyz="0 0 0" rpy="0 0 0"/>
      <geometry>
        <cylinder radius="0.2" length="0.1"/>
      </geometry>
      <material name="black"/>
    </visual>
  </link>

  <!-- Joints, reversed: elbow_joint before shoulder_joint -->
  <joint name="elbow_joint" type="revolute">
    <parent link="upper_arm"/>
    <child link="forearm"/>
    <origin xyz="0 0 0.9" rpy="0 0 0"/>
    <axis xyz="0 1 0"/>
    <limit lower="-1.57" upper="1.57" effort="100.0" velocity="1.0"/>
  </joint>

  <joint name="shoulder_joint" type="revolute">
    <parent link="base_link"/>
    <child link="upper_arm"/>
    <origin xyz="0 0 0.1" rpy="0 0 0"/>
    <axis xyz="0 0 1"/>
    <limit lower="-1.57" upper="1.57" effort="100.0" velocity="1.0"/>
  </joint>

</robot>
