<?xml version="1.0" ?>
<!-- =================================================================================== -->
<!-- |    This document was autogenerated by xacro from /workspaces/src/flexiv_description/urdf/flexiv.urdf.xacro | -->
<!-- |    EDITING THIS FILE BY HAND IS NOT RECOMMENDED                                 | -->
<!-- =================================================================================== -->
<!-- 
  COPYRIGHT & LICENSE ATTRIBUTION:
  Derived from the flexiv_description project.
  Original Repository: https://github.com/flexivrobotics/flexiv_description
  Original License: Apache License, Version 2.0

  MODIFICATION NOTICE:
  Modified by RobJMal in 2026. 
  Changes made: Updated package paths for visual and collision mesh resources.
-->
<robot name="Enlight-L">
  <material name="flexiv_black">
    <color rgba="0.22 0.22 0.22 1"/>
  </material>
  <joint name="base_joint" type="fixed">
    <parent link="world"/>
    <child link="base_link"/>
    <origin rpy="0.0 0.0 0.0" xyz="0.0 0.0 0.0"/>
  </joint>
  <joint name="joint1" type="revolute">
    <parent link="base_link"/>
    <child link="link1"/>
    <origin rpy="0.0 0.0 0.0" xyz="0.0 0.0 0.146"/>
    <axis xyz="0 0 1"/>
    <limit effort="100" lower="-6.3705" upper="6.3705" velocity="2.0944"/>
    <safety_controller k_position="100.0" k_velocity="40.0" soft_lower_limit="-6.2832" soft_upper_limit="6.2832"/>
  </joint>
  <joint name="joint2" type="revolute">
    <parent link="link1"/>
    <child link="link2"/>
    <origin rpy="1.5707963267948966 0.0 0.0" xyz="0.0 -0.037 0.114"/>
    <axis xyz="0 0 1"/>
    <limit effort="100" lower="-2.1817" upper="2.1817" velocity="2.0944"/>
    <safety_controller k_position="100.0" k_velocity="40.0" soft_lower_limit="-2.0944" soft_upper_limit="2.0944"/>
  </joint>
  <joint name="joint3" type="revolute">
    <parent link="link2"/>
    <child link="link3"/>
    <origin rpy="-1.5707963267948966 0.0 0.0" xyz="0.0 0.181 -0.037"/>
    <axis xyz="0 0 1"/>
    <limit effort="100" lower="-6.3705" upper="6.3705" velocity="2.0944"/>
    <safety_controller k_position="100.0" k_velocity="40.0" soft_lower_limit="-6.2832" soft_upper_limit="6.2832"/>
  </joint>
  <joint name="joint4" type="revolute">
    <parent link="link3"/>
    <child link="link4"/>
    <origin rpy="-1.5707963267948966 0.0 0.0" xyz="0.0 0.037 0.109"/>
    <axis xyz="0 0 1"/>
    <limit effort="100" lower="-2.1817" upper="2.1817" velocity="2.0944"/>
    <safety_controller k_position="100.0" k_velocity="40.0" soft_lower_limit="-2.0944" soft_upper_limit="2.0944"/>
  </joint>
  <joint name="joint5" type="revolute">
    <parent link="link4"/>
    <child link="link5"/>
    <origin rpy="1.5707963267948966 0.0 0.0" xyz="0.0 -0.156 -0.037"/>
    <axis xyz="0 0 1"/>
    <limit effort="21" lower="-6.3705" upper="6.3705" velocity="6.0214"/>
    <safety_controller k_position="100.0" k_velocity="40.0" soft_lower_limit="-6.2832" soft_upper_limit="6.2832"/>
  </joint>
  <joint name="joint6" type="revolute">
    <parent link="link5"/>
    <child link="link6"/>
    <origin rpy="1.5707963267948966 0.0 0.0" xyz="0.0 -0.0261 0.124"/>
    <axis xyz="0 0 1"/>
    <limit effort="21" lower="-2.1817" upper="2.1817" velocity="6.0214"/>
    <safety_controller k_position="100.0" k_velocity="40.0" soft_lower_limit="-2.0944" soft_upper_limit="2.0944"/>
  </joint>
  <joint name="joint7" type="revolute">
    <parent link="link6"/>
    <child link="link7"/>
    <origin rpy="-1.5707963267948966 0.0 0.0" xyz="0.0 0.134 -0.0261"/>
    <axis xyz="0 0 1"/>
    <limit effort="21" lower="-6.3705" upper="6.3705" velocity="6.0214"/>
    <safety_controller k_position="100.0" k_velocity="40.0" soft_lower_limit="-6.2832" soft_upper_limit="6.2832"/>
  </joint>
  <joint name="link7_to_flange" type="fixed">
    <parent link="link7"/>
    <child link="flange"/>
    <origin rpy="0.0 0.0 0.0" xyz="0.0 0.0 0.048"/>
  </joint>
  <link name="world">
      </link>
  <link name="base_link">
    <origin rpy="0.0 0.0 0.0" xyz="-0.0001 0.0019 0.0721"/>
    <mass value="2.456"/>
    <inertia ixx="0.0072" ixy="0.0" ixz="0.0" iyy="0.0068" iyz="-0.0002" izz="0.0048"/>
    <visual name="shell">
      <origin rpy="0 0 0" xyz="0 0 0"/>
      <geometry>
        <mesh filename="meshes/Enlight-L/visual/link0.obj"/>
      </geometry>
    </visual>
    <collision name="convex_mesh">
      <origin rpy="0 0 0" xyz="0 0 0"/>
      <geometry>
        <mesh filename="meshes/Enlight-L/collision/link0.stl"/>
      </geometry>
    </collision>
    <workspace>
      <origin rpy="0.0 0.0 0.0" xyz="0.0 0.0 0.25"/>
      <geometry>
        <sphere radius="0.6"/>
      </geometry>
    </workspace>
  </link>
  <link name="link1">
    <origin rpy="0.0 0.0 0.0" xyz="0.0001 0.0105 0.0766"/>
    <mass value="2.484"/>
    <inertia ixx="0.0096" ixy="0.0" ixz="0.0" iyy="0.0094" iyz="0.0007" izz="0.0031"/>
    <visual name="shell">
      <origin rpy="0 0 0" xyz="0 0 0"/>
      <geometry>
        <mesh filename="meshes/Enlight-L/visual/link1.obj"/>
      </geometry>
    </visual>
    <collision name="convex_mesh">
      <origin rpy="0 0 0" xyz="0 0 0"/>
      <geometry>
        <mesh filename="meshes/Enlight-L/collision/link1.stl"/>
      </geometry>
    </collision>
  </link>
  <link name="link2">
    <origin rpy="0.0 0.0 0.0" xyz="0.0001 0.0861 -0.0262"/>
    <mass value="2.698"/>
    <inertia ixx="0.0133" ixy="0.0" ixz="0.0" iyy="0.0038" iyz="-0.0022" izz="0.0129"/>
    <visual name="shell">
      <origin rpy="0 0 0" xyz="0 0 0"/>
      <geometry>
        <mesh filename="meshes/Enlight-L/visual/link2.obj"/>
      </geometry>
    </visual>
    <collision name="convex_mesh">
      <origin rpy="0 0 0" xyz="0 0 0"/>
      <geometry>
        <mesh filename="meshes/Enlight-L/collision/link2.stl"/>
      </geometry>
    </collision>
  </link>
  <link name="link3">
    <origin rpy="0.0 0.0 0.0" xyz="0.0001 -0.0105 0.073"/>
    <mass value="2.475"/>
    <inertia ixx="0.009" ixy="0.0" ixz="0.0" iyy="0.0088" iyz="-0.0007" izz="0.0031"/>
    <visual name="shell">
      <origin rpy="0 0 0" xyz="0 0 0"/>
      <geometry>
        <mesh filename="meshes/Enlight-L/visual/link3.obj"/>
      </geometry>
    </visual>
    <collision name="convex_mesh">
      <origin rpy="0 0 0" xyz="0 0 0"/>
      <geometry>
        <mesh filename="meshes/Enlight-L/collision/link3.stl"/>
      </geometry>
    </collision>
  </link>
  <link name="link4">
    <origin rpy="0.0 0.0 0.0" xyz="0.0002 -0.0643 -0.019"/>
    <mass value="1.96"/>
    <inertia ixx="0.0087" ixy="0.0" ixz="0.0" iyy="0.0026" iyz="0.0019" izz="0.0083"/>
    <visual name="shell">
      <origin rpy="0 0 0" xyz="0 0 0"/>
      <geometry>
        <mesh filename="meshes/Enlight-L/visual/link4.obj"/>
      </geometry>
    </visual>
    <collision name="convex_mesh">
      <origin rpy="0 0 0" xyz="0 0 0"/>
      <geometry>
        <mesh filename="meshes/Enlight-L/collision/link4.stl"/>
      </geometry>
    </collision>
  </link>
  <link name="link5">
    <origin rpy="0.0 0.0 0.0" xyz="0.0002 0.01 0.0841"/>
    <mass value="1.458"/>
    <inertia ixx="0.0053" ixy="0.0" ixz="0.0" iyy="0.0053" iyz="0.0003" izz="0.0014"/>
    <visual name="shell">
      <origin rpy="0 0 0" xyz="0 0 0"/>
      <geometry>
        <mesh filename="meshes/Enlight-L/visual/link5.obj"/>
      </geometry>
    </visual>
    <collision name="convex_mesh">
      <origin rpy="0 0 0" xyz="0 0 0"/>
      <geometry>
        <mesh filename="meshes/Enlight-L/collision/link5.stl"/>
      </geometry>
    </collision>
  </link>
  <link name="link6">
    <origin rpy="0.0 0.0 0.0" xyz="0.0003 0.0691 -0.0169"/>
    <mass value="1.384"/>
    <inertia ixx="0.0041" ixy="0.0" ixz="0.0" iyy="0.0016" iyz="-0.0008" izz="0.0039"/>
    <visual name="shell">
      <origin rpy="0 0 0" xyz="0 0 0"/>
      <geometry>
        <mesh filename="meshes/Enlight-L/visual/link6.obj"/>
      </geometry>
    </visual>
    <collision name="convex_mesh">
      <origin rpy="0 0 0" xyz="0 0 0"/>
      <geometry>
        <mesh filename="meshes/Enlight-L/collision/link6.stl"/>
      </geometry>
    </collision>
  </link>
  <link name="link7">
    <origin rpy="0.0 0.0 0.0" xyz="0.0006 0.0 0.0105"/>
    <mass value="0.445"/>
    <inertia ixx="0.0037" ixy="0.0" ixz="0.0" iyy="0.0037" iyz="0.0" izz="0.0004"/>
    <visual name="shell">
      <origin rpy="0 0 0" xyz="0 0 0"/>
      <geometry>
        <mesh filename="meshes/Enlight-L/visual/link7.obj"/>
      </geometry>
    </visual>
    <collision name="convex_mesh">
      <origin rpy="0 0 0" xyz="0 0 0"/>
      <geometry>
        <mesh filename="meshes/Enlight-L/collision/link7.stl"/>
      </geometry>
    </collision>
  </link>
  <link name="flange">
    </link>
</robot>
